Loading Excel file: Z:\Business Unit Team Management\Chargebacks\8. Interest & Charges (Chargebacks) (LD1700 Active+6 years)-Classification Internal & Confidential\Chennai\3.0 India\4. Work Allocation\2025\DRS Manual files\July\08072025\07jul2025_part4_srini.xlsx
Extracted Refund Date: 07-Jul-2025
---------------------------------------------------------------------------
TypeError                                 Traceback (most recent call last)
C:\ProgramData\App-V\95FD7873-726E-40E9-B477-CC4010411846\9727BF3A-F7F8-45A4-AD38-2F35B6E0FB2A\Root\lib\site-packages\pandas\core\tools\datetimes.py in _convert_listlike(arg, box, format, name, tz)
    443             try:
--> 444                 values, tz = tslib.datetime_to_datetime64(arg)
    445                 return DatetimeIndex._simple_new(values, name=name, tz=tz)

pandas/_libs/tslib.pyx in pandas._libs.tslib.datetime_to_datetime64 (pandas\_libs\tslib.c:33275)()

TypeError: Unrecognized value type: <class 'str'>

During handling of the above exception, another exception occurred:

ValueError                                Traceback (most recent call last)
<ipython-input-90-5f1d997b621e> in <module>()
      5 
      6 df = pd.read_excel(excel_file_path)
----> 7 df['Hit Date DT'] = pd.to_datetime(df['Hit Date'], format='%d%b%Y')
      8 df.sort_values(by=['Brand', 'Account'], inplace=True)
      9 

C:\ProgramData\App-V\95FD7873-726E-40E9-B477-CC4010411846\9727BF3A-F7F8-45A4-AD38-2F35B6E0FB2A\Root\lib\site-packages\pandas\core\tools\datetimes.py in to_datetime(arg, errors, dayfirst, yearfirst, utc, box, format, exact, unit, infer_datetime_format, origin)
    507     elif isinstance(arg, ABCSeries):
    508         from pandas import Series
--> 509         values = _convert_listlike(arg._values, False, format)
    510         result = Series(values, index=arg.index, name=arg.name)
    511     elif isinstance(arg, (ABCDataFrame, MutableMapping)):

C:\ProgramData\App-V\95FD7873-726E-40E9-B477-CC4010411846\9727BF3A-F7F8-45A4-AD38-2F35B6E0FB2A\Root\lib\site-packages\pandas\core\tools\datetimes.py in _convert_listlike(arg, box, format, name, tz)
    445                 return DatetimeIndex._simple_new(values, name=name, tz=tz)
    446             except (ValueError, TypeError):
--> 447                 raise e
    448 
    449     if arg is None:

C:\ProgramData\App-V\95FD7873-726E-40E9-B477-CC4010411846\9727BF3A-F7F8-45A4-AD38-2F35B6E0FB2A\Root\lib\site-packages\pandas\core\tools\datetimes.py in _convert_listlike(arg, box, format, name, tz)
    412                     try:
    413                         result = tslib.array_strptime(arg, format, exact=exact,
--> 414                                                       errors=errors)
    415                     except tslib.OutOfBoundsDatetime:
    416                         if errors == 'raise':

pandas/_libs/tslib.pyx in pandas._libs.tslib.array_strptime (pandas\_libs\tslib.c:63619)()

ValueError: time data '03JUL25' does not match format '%d%b%Y' (match)
